Workbook

Sheet Q1
XEX1: =VLOOKUP(XEW1,INDIRECT($B$4&"!$A$1:$B$800"),2,0) -> #N/A | XFC1: VLOOKUP(VALUE(K5),$H$5:$I$17,2,0)
A2: Q1. Find out the country, name and date from the next three sheets. | H2: Q2. | N2: Q3.
A4: OrderID | B4: Country | C4: Output Country | D4: Output Date | E4: Output Name | H4: OrderID | I4: Order Date | K4: OrderID | L4: Order Date | N4: OrderID | O4: Name
A5: 10248 | B5: =_xlfn.XLOOKUP(A5,Country!A1:A800,Country!B1:B800,0,0) -> UK | C5: UK | D5: 37818 | E5: Buchanan | H5: 10248 | I5: 38466 | K5: 10248 | L5: =_xlfn.XLOOKUP(K5,Date!A1:A800,Date!B1:B800,0,0) -> 37818 | N5: 10248 | O5: =_xlfn.XLOOKUP(N5,Name!A1:A800,Name!B1:B800,0,0) -> Buchanan
A6: 10249 | B6: =_xlfn.XLOOKUP(A6,Country!A2:A801,Country!B2:B801,0,0) -> UK | C6: UK | D6: 37812 | E6: Suyama | H6: 10249 | I6: 38473 | K6: 10249 | L6: =_xlfn.XLOOKUP(K6,Date!A2:A801,Date!B2:B801,0,0) -> 37812 | N6: 10249 | O6: =_xlfn.XLOOKUP(N6,Name!A2:A801,Name!B2:B801,0,0) -> Suyama
A7: 10250 | B7: =_xlfn.XLOOKUP(A7,Country!A3:A802,Country!B3:B802,0,0) -> USA | C7: USA | D7: 37814 | E7: Lee | H7: 10250 | I7: 38471 | K7: 10250 | L7: =_xlfn.XLOOKUP(K7,Date!A3:A802,Date!B3:B802,0,0) -> 37814 | N7: 10250 | O7: =_xlfn.XLOOKUP(N7,Name!A3:A802,Name!B3:B802,0,0) -> Lee
A8: 10251 | B8: =_xlfn.XLOOKUP(A8,Country!A4:A803,Country!B4:B803,0,0) -> USA | C8: USA | D8: 37817 | E8: Leverling | H8: 10251 | I8: 38473 | K8: 10251 | L8: =_xlfn.XLOOKUP(K8,Date!A4:A803,Date!B4:B803,0,0) -> 37817 | N8: 10251 | O8: =_xlfn.XLOOKUP(N8,Name!A4:A803,Name!B4:B803,0,0) -> Leverling
A9: 10252 | B9: =_xlfn.XLOOKUP(A9,Country!A5:A804,Country!B5:B804,0,0) -> USA | C9: USA | D9: 37813 | E9: Lee | H9: 10252 | I9: 38470 | N9: 10252 | O9: =_xlfn.XLOOKUP(N9,Name!A5:A804,Name!B5:B804,0,0) -> Lee
A10: 10253 | B10: =_xlfn.XLOOKUP(A10,Country!A6:A805,Country!B6:B805,0,0) -> USA | C10: USA | D10: 37818 | E10: Leverling | H10: 10253 | I10: 38472 | N10: 10253 | O10: =_xlfn.XLOOKUP(N10,Name!A6:A805,Name!B6:B805,0,0) -> Leverling
A11: 10254 | B11: =_xlfn.XLOOKUP(A11,Country!A7:A806,Country!B7:B806,0,0) -> 0 | C11: UK | D11: 37825 | E11: Buchanan | H11: 10254 | I11: 38469 | N11: 10254 | O11: =_xlfn.XLOOKUP(N11,Name!A7:A806,Name!B7:B806,0,0) -> Buchanan
A12: 10255 | B12: =_xlfn.XLOOKUP(A12,Country!A8:A807,Country!B8:B807,0,0) -> 0 | C12: UK | D12: 37817 | E12: Dodsworth | H12: 10255 | I12: 38464 | N12: 10255 | O12: =_xlfn.XLOOKUP(N12,Name!A8:A807,Name!B8:B807,0,0) -> Dodsworth
A13: 10256 | B13: =_xlfn.XLOOKUP(A13,Country!A9:A808,Country!B9:B808,0,0) -> USA | C13: USA | D13: 37819 | E13: Leverling | H13: 10256 | I13: =I11+10 -> 38479 | N13: 10256 | O13: =_xlfn.XLOOKUP(N13,Name!A9:A808,Name!B9:B808,0,0) -> Leverling
A14: 10257 | B14: =_xlfn.XLOOKUP(A14,Country!A10:A809,Country!B10:B809,0,0) -> USA | C14: USA | D14: 37824 | E14: Lee | H14: 10257 | I14: =I12+10 -> 38474 | N14: 10257 | O14: =_xlfn.XLOOKUP(N14,Name!A10:A809,Name!B10:B809,0,0) -> Lee
A15: 10258 | B15: =_xlfn.XLOOKUP(A15,Country!A11:A810,Country!B11:B810,0,0) -> USA | C15: USA | D15: 37825 | E15: Davolio | H15: 10258 | I15: =I13+10 -> 38489 | N15: 10258 | O15: =_xlfn.XLOOKUP(N15,Name!A11:A810,Name!B11:B810,0,0) -> Davolio
A16: 10259 | B16: =_xlfn.XLOOKUP(A16,Country!A12:A811,Country!B12:B811,0,0) -> USA | C16: USA | D16: 37827 | E16: Lee | H16: 10259 | I16: =I14+10 -> 38484 | N16: 10259 | O16: =_xlfn.XLOOKUP(N16,Name!A12:A811,Name!B12:B811,0,0) -> Lee
A17: 10260 | B17: =_xlfn.XLOOKUP(A17,Country!A13:A812,Country!B13:B812,0,0) -> USA | C17: USA | D17: 37831 | E17: Lee | H17: 10260 | I17: =I15+10 -> 38499 | N17: 10260 | O17: =_xlfn.XLOOKUP(N17,Name!A13:A812,Name!B13:B812,0,0) -> Lee

Sheet Name
A1: OrderID | B1: Sales Person
A2: 10248 | B2: Buchanan
A3: 10249 | B3: Suyama
A4: 10250 | B4: Lee
A5: 10251 | B5: Leverling
A6: 10252 | B6: Lee
A7: 10253 | B7: Leverling
A8: 10254 | B8: Buchanan
A9: 10255 | B9: Dodsworth
A10: 10256 | B10: Leverling
A11: 10257 | B11: Lee
A12: 10258 | B12: Davolio
A13: 10259 | B13: Lee
... A800: 11057 | B800: Leverling

Sheet Date
A1: OrderID | B1: Order Date
A2: 11057 | B2: 38473
A3: 11056 | B3: 38473
A4: 11053 | B4: 38471
A5: 11052 | B5: 38473
A6: 11048 | B6: 38472
A7: 11047 | B7: 38473
A8: 11046 | B8: 38466
A9: 11044 | B9: 38473
A10: 11043 | B10: 38471
A11: 11042 | B11: 38473
A12: 11041 | B12: 38470
A13: 11038 | B13: 38472
... A800: 10248 | B800: 37818

Sheet Country
A1: OrderID | B1: Country
A2: 10248 | B2: UK
A3: 10249 | B3: UK
A4: 10254 | B4: UK
A5: 10255 | B5: UK
A6: 10263 | B6: UK
A7: 10264 | B7: UK
A8: 10269 | B8: UK
A9: 10271 | B9: UK
A10: 10272 | B10: UK
A11: 10274 | B11: UK
A12: 10289 | B12: UK
A13: 10291 | B13: UK
... A800: 11057 | B800: USA

Sheet Q2
B1: Q1 | C1: Q2 | D1: Q3 | E1: Q4
A2: Product1 | B2: 224789 | C2: 127750 | D2: 188622 | E2: 215972
A3: Product2 | B3: 273617 | C3: 310450 | D3: 16484 | E3: 204802
A4: Product3 | B4: 180523 | C4: 169481 | D4: 197774 | E4: 275837
A5: Product4 | B5: 26854 | C5: 157752 | D5: 56231 | E5: 243285 | H5: Q1 | I5: Product1 | J5: =_xlfn.XLOOKUP(I5,A1:A7,B1:B7,0,0) -> 224789
A6: Product5 | B6: 122420 | C6: 254307 | D6: 161682 | E6: 116720
A7: Product6 | B7: 15618 | C7: 290770 | D7: 192488 | E7: 280013 | H7: 1.Find the value of given quarter and given product according to the above validation

Sheet Q3
A1: OrderID | B1: Sales Person | H1: OrderID | I1: Sales Person
A2: 10248 | B2: Buchanan | H2: 10250 | I2: =VLOOKUP(H2,A1:B9,2,FALSE) -> Lee
A3: 10249 | B3: Suyama | H3: 10251 | I3: =VLOOKUP(H3,A2:B10,2,FALSE) -> Leverling
A4: 10250 | B4: Lee | H4: 10252 | I4: =VLOOKUP(H4,A3:B11,2,FALSE) -> Dodsworth
A5: 10251 | B5: Leverling
A6: 10252 | B6: Dodsworth
A7: 10253 | B7: Leverling
A8: 10254 | B8: Buchanan
A9: 10255 | B9: Dodsworth

Sheet Q4
A1: 88 | D1: {=SUM(LARGE(A1:A22,{1,2,3,4,5}))} -> 437 | F1: Find the sum of top 5 sales
A2: 62
A3: 87
A4: 90
A5: 80
A6: 54
A7: 86
A8: 66
A9: 47
A10: 71
A11: 52
A12: 49
A13: 22
... A22: 68

Sheet Q5
A1: Name | B1: DOB | E1: Based on the data provided below, find out how many people are born in the month of Jan, Feb,…Nov, Dec.
A2: Adella | B2: 20441 | C2: Dec
A3: Allen | B3: 23249 | C3: Aug | F3: Month | G3: Count
A4: Anne | B4: 17469 | C4: Oct | F4: Jan | G4: =COUNTIF($C$1:$C$76,F4) -> 4
A5: Beverly | B5: 25935 | C5: Jan | F5: Feb | G5: =COUNTIF($C$1:$C$76,F5) -> 6
A6: Bonnie | B6: 22643 | C6: Dec | F6: Mar | G6: =COUNTIF($C$1:$C$76,F6) -> 6
A7: Brian | B7: 29144 | C7: Oct | F7: Apr | G7: =COUNTIF($C$1:$C$76,F7) -> 5
A8: Carol | B8: 26025 | C8: Apr | F8: May | G8: =COUNTIF($C$1:$C$76,F8) -> 7
A9: Christopher | B9: 24420 | C9: Nov | F9: Jun | G9: =COUNTIF($C$1:$C$76,F9) -> 4
A10: Coral | B10: 22596 | C10: Nov | F10: Jul | G10: =COUNTIF($C$1:$C$76,F10) -> 7
A11: Daryl | B11: 13755 | C11: Aug | F11: Aug | G11: =COUNTIF($C$1:$C$76,F11) -> 7
A12: David | B12: 22784 | C12: May | F12: Sep | G12: =COUNTIF($C$1:$C$76,F12) -> 6
A13: David | B13: 20756 | C13: Oct | F13: Oct | G13: =COUNTIF($C$1:$C$76,F13) -> 13
A14: David | B14: 22860 | C14: Aug | F14: Nov | G14: =COUNTIF($C$1:$C$76,F14) -> 2
A15: Deborah | B15: 20638 | C15: Jul | F15: Dec | G15: =COUNTIF($C$1:$C$76,F15) -> 8
A16: Dolores | B16: 25633 | C16: Mar
A17: Donna | B17: 22687 | C17: Feb
A18: Donna | B18: 26379 | C18: Mar
A19: Edward | B19: 23110 | C19: Apr
A20: Eleanor | B20: 21435 | C20: Sep
A21: Eva | B21: 26534 | C21: Aug
A22: Frank | B22: 16559 | C22: May
A23: Fred | B23: 21918 | C23: Jan
A24: George | B24: 23400 | C24: Jan
A25: Harry | B25: 11624 | C25: Oct
A26: James | B26: 16109 | C26: Feb
A27: James | B27: 14328 | C27: Mar
... A76: William | B76: 22175 | C76: Sep
B78: Month
B79: 1
B80: 2
B81: 3
B82: 4
B83: 5
B84: 6
B85: 7
B86: 8
B87: 9
B88: 10
B89: 11
...

Sheet Q6
A2: Date | B2: 40556 | D2: Status | E2: Unsolved
A3: Q10. | B3: See the Graph and Put the validation in following table:
B6: Things | C6: Fruit/Game | D6: Taste/country | E6: Color/Player | F6: Ingradients/Item
B7: Fruits | C7: Cricket | D7: India | E7: Sachin | F7: Bat & Ball | K7: Things
K8: Fruits
K9: Games
B10: Select things from things colomn either Fruit or Games.
B11: II cloumn fills with name of either fruits or a game
B12: the respective coulmns will filled as per the bottom table
I13: Fruits | M13: Games
I14: Apple | M14: Cricket
I15: Mango | M15: Bollibal
I16: Grapes | M16: Tanish
G19: Fruit | H19: Taste | I19: Color | J19: Ingradients | L19: Games | M19: Country | N19: Player | O19: Item
G20: Apple | H20: Sweet | I20: Redish | J20: Vitamins A,B,C | L20: Cricket | M20: England | N20: Sachin | O20: Bat & Ball
G21: Mango | H21: Swear | I21: Yellow | J21: Vitamin C | L21: Bollibal | M21: India | N21: Bakham | O21: Handball
G22: Grapes | H22: Swear | I22: Green | J22: Vitamin C | L22: Tanish | M22: America | N22: Saniya | O22: Rackets & Ball

Sheet Q7
A1: Date | B1: Amount | C1: AcctType | D1: OpenedBy | E1: Branch | F1: Customer
A2: 38961 | B2: 5000 | C2: IRA | D2: New Accts | E2: Central | F2: Existing | I2: Answer the Following Questions on the basic Row Data Given Below
A3: 38961 | B3: 14571 | C3: CD | D3: Teller | E3: Central | F3: New
A4: 38961 | B4: 500 | C4: Checking | D4: New Accts | E4: Central | F4: Existing | I4: Q1. What is Total new deposite amount for each branch?
A5: 38961 | B5: 15000 | C5: CD | D5: New Accts | E5: Central | F5: Existing
A6: 38961 | B6: 4623 | C6: Savings | D6: New Accts | E6: North County | F6: Existing | I6: Q2. How many accounts were opened at each branch broken down by account type?
A7: 38961 | B7: 8721 | C7: Savings | D7: New Accts | E7: Westside | F7: New
A8: 38961 | B8: 15276 | C8: Savings | D8: New Accts | E8: North County | F8: Existing | I8: Q3. What is the dollar distrubution of the different account type?
A9: 38961 | B9: 5000 | C9: Savings | D9: New Accts | E9: Westside | F9: Existing
A10: 38961 | B10: 15759 | C10: CD | D10: Teller | E10: Westside | F10: Existing | I10: Q4. What type of accounts do a tellers open most oftem?
A11: 38961 | B11: 12000 | C11: CD | D11: New Accts | E11: Westside | F11: Existing
A12: 38961 | B12: 7177 | C12: Savings | D12: Teller | E12: North County | F12: Existing | I12: Q5. How does the central branch compare to the other two branches?
A13: 38961 | B13: 6837 | C13: Savings | D13: New Accts | E13: Westside | F13: Existing
A14: 38961 | B14: 3171 | C14: Checking | D14: New Accts | E14: Westside | F14: Existing | I14: Q6. In which branch do tellers open the most checking accounts for new customers?
A15: 38961 | B15: 50000 | C15: Savings | D15: New Accts | E15: Central | F15: Existing
A16: 38961 | B16: 4690 | C16: Checking | D16: New Accts | E16: North County | F16: New
A17: 38961 | B17: 12438 | C17: Checking | D17: New Accts | E17: Central | F17: Existing
A18: 38961 | B18: 5000 | C18: Checking | D18: New Accts | E18: North County | F18: Existing
A19: 38961 | B19: 7000 | C19: Savings | D19: New Accts | E19: North County | F19: New
A20: 38961 | B20: 11957 | C20: Checking | D20: New Accts | E20: Central | F20: Existing
A21: 38961 | B21: 13636 | C21: CD | D21: New Accts | E21: North County | F21: Existing
A22: 38961 | B22: 16000 | C22: CD | D22: New Accts | E22: Central | F22: New
A23: 38961 | B23: 5879 | C23: Checking | D23: New Accts | E23: Central | F23: Existing
A24: 38961 | B24: 4000 | C24: Savings | D24: New Accts | E24: Central | F24: Existing
A25: 38962 | B25: 10000 | C25: CD | D25: Teller | E25: North County | F25: Existing
A26: 38962 | B26: 7427 | C26: Checking | D26: New Accts | E26: North County | F26: Existing
... A713: 38989 | B713: 4000 | C713: Checking | D713: Teller | E713: North County | F713: Existing

Sheet Q8
A1: Find the cummulative investment for each year. E.g. In year 7, the cumulative investment should be summation of year 1 to 7
A3: Year | B3: 1 | C3: 2 | D3: 3 | E3: 4 | F3: 5 | G3: 6 | H3: 7 | I3: 8 | J3: 9 | K3: 10 | L3: 11 | M3: 12 | N3: 13 | O3: 14 | P3: 15 | Q3: 16 | R3: 17 | S3: 18 | T3: 19 | U3: 20
A4: Investment | B4: -1266.41 | C4: -1266.41 | D4: -6090 | E4: -1266.41 | F4: -1266.41 | G4: -9839 | H4: -1266.41 | I4: -1266.41 | J4: -3489 | K4: -1266.41 | L4: -1266.41 | M4: -1266.41 | N4: -1266.41 | O4: -1266.41 | P4: -1266.41 | Q4: -1266.41 | R4: -1266.41 | S4: -1266.41 | T4: -1266.41 | U4: -1266.41
A5: Cummulative Investment | B5: -1266.41 | C5: =B4+C4 -> -2532.82 | D5: =B4+C4+D4 -> -8622.82 | E5: =B4+C4+D4+E4 -> -9889.23 | F5: =B4+C4+D4+E4+F4 -> -11155.64 | G5: =F5+G4 -> -20994.64 | H5: =G5+H4 -> -22261.05 | I5: =H5+I4 -> -23527.46 | J5: =I5+J4 -> -27016.46 | K5: =J5+K4 -> -28282.87 | L5: =K5+L4 -> -29549.28 | M5: =L5+M4 -> -30815.69 | N5: =M5+N4 -> -32082.1 | ... U5: =T5+U4 -> -40946.97

Sheet Q9
A1: 100 | F1: Validate Column A1:A20, So that user can't type duplicate value, value entered by the user should be between 100 to 300 and and also it should be the numeric value.

Sheet Q10
A1: Q.1 | B1: How to delete the blank cell from the range? Please specify the steps.
B3: 56 | C3: 53 | E3: 30 | G3: 99
B4: 67 | D4: 44 | G4: 31
C5: 17 | E5: 66 | F5: 12 | G5: =
D6: 38 | E6: 44 | G6: 43
B7: 13 | C7: 86 | D7: 94 | F7: 98 | G7: 37
C8: 74 | E8: 36 | F8: 32
B9: 26 | C9: 38 | E9: 35 | G9: 93
A11: Ans:- | B11: 1)Select the cell rangs 2) go to home tab 3) find Select 4) Go to special dialog box 5)select Blanks and click OK 6)Right-click on any of the selected blank cells and click Delete
A13: Q. 2 | B13: If we put the value >0 to <2000 in column B then column C should be red.
B15: Value | C15: Cell Color
B16: 1809
B17: -10
B18: -200
B19: 800
B20: -1691
B21: 1500
B22: 3500
A24: Q.3 | B24: In the below table have given Member Name and DOJ. Please find how many Years and Days have been spent
B26: Name | C26: Doj | D26: Result
B27: Agent1 | C27: 40239 | D27: =DATEDIF(B27, TODAY(),"y") -> #VALUE!
B28: Agent2 | C28: 40331 | D28: {=DATEDIF(G36B28, TODAY(), "Y") & " Years " & DATEDIF(B28, TODAY(), "YD") & " Days"} -> #NAME?
B29: Agent3 | C29: 39915
B30: Agent4 | C30: 40604
B31: Agent5 | C31: 40331
B32: Agent6 | C32: 39915
B33: Agent7 | C33: 40604
B34: Agent8 | C34: 40331
B35: Agent9 | C35: 39915
A38: Q.4 | B38: Please highlight the row of those agent's age is <24 and >27.
B40: Name | C40: Age | D40: Designation | E40: Dept
B41: Agent1 | C41: 29 | D41: Asso | E41: MIS
B42: Agent2 | C42: 33 | D42: Sr. Asso | E42: MIS
B43: Agent3 | C43: 27 | D43: AM | E43: MIS
B44: Agent4 | C44: 22 | D44: Asso | E44: MIS
B45: Agent5 | C45: 24 | D45: Sr. Asso | E45: MIS
B46: Agent6 | C46: 32 | D46: AM | E46: MIS
B47: Agent7 | C47: 26 | D47: Asso | E47: MIS
B48: Agent8 | C48: 25 | D48: Sr. Asso | E48: MIS
B49: Agent9 | C49: 28 | D49: AM | E49: MIS
...
